## 1. 함수 내에서 예외를 throw하면 호출된 곳에서 예외를 처리한다.(스택풀기)
```C++
#include <iostream>
using namespace std;

void Divide(int num1, int num2)
{
	if (num2 == 0)
		throw num2;//1. 함수 정의부에서 예외를 던지면

	cout << "나눗셈의 몫: " << num1 / num2 << endl;
	cout << "나눗셈의 나머지: " << num1 % num2 << endl;
}

int main(void)
{
	int num1, num2;
	cout << "두 개의 숫자 입력: ";
	cin >> num1 >> num2;

	try
	{
		Divide(num1, num2);//2. 함수를 호출한 곳에서 예외데이터를 받아 예외로 감지된다.
		cout << "나눗셈을 마쳤습니다." << endl;
	}
	catch (int expn)//3. 호출한 곳에서 예외를 처리한다.
	{
		cout << "제수는 " << expn << "이 될 수 없습니다." << endl;
		cout << "프로그램을 다시 실행하세요." << endl;
	}

	return 0;
}
```

## 2. 스택이 쌓인 순서의 역순으로 스택이 해제되면서 에러코드가 전달된다.
```C++
#include <iostream>
using namespace std;

void SimpleFuncOne(void);
void SimpleFuncTwo(void);
void SimpleFuncThree(void);

int main(void)//1. main 스택
{
	try
	{
		SimpleFuncOne();// 9. 메인으로 에러전달.
	}
	catch (int expn)
	{
		cout << "예외코드: " << expn << endl;
	}
	return 0;
}

void SimpleFuncOne(void)// 2. one 스택 8.one 스택 해제
{
	cout << "SimpleFuncOne(void)" << endl;
	SimpleFuncTwo();
}
void SimpleFuncTwo(void)// 3. two 스택 7.two 스택 해제
{
	cout << "SimpleFuncTwo(void)" << endl;
	SimpleFuncThree();
}
void SimpleFuncThree(void) //4. three 스택 6.three 스택 해제
{
	cout << "SimpleFuncThree(void)" << endl;
	throw - 1;// 5. 에러 데이터 
}

```
## 3. 예외 데이터의 자료형과 Catch의 파라미터의 자료형이 불일치할 때.

```C++
  void SimpleFuncOne(void)  
{
	throw - 1; // 1.int형 예외데이터를 발생.
}
	try
	{
		SimpleFuncOne();
	}
	catch (char expn)// 2. char형의 파라미터 -> 예외를 처리하지 않게 된다.
	{
		cout << "예외코드: " << expn << endl;
	}
```
> 자료형이 불일치하면 예외를 처리하지 않는다.
> 
## 4. 하나의 try, 다수의 catch
```C++
#include <iostream>
#include <cstring>
#include <cmath>
using namespace std;

int StoI(char* str)
{
	int len = strlen(str);
	int num = 0;

	if (len != 0 && str[0] == '0')
		throw 0;

	for (int i = 0; i < len; i++)
	{
		if (str[i] < '0' || str[i]>'9')
			throw str[i];

		num += (int)(pow((double)10, (len - 1) - i) * (str[i] + (7 - '7')));
	}
	return num;
}

int main(void)
{
	char str1[100];
	char str2[200];

	while (1)
	{
		cout << "두 개의 숫자 입력: ";
		cin >> str1 >> str2;

		try
		{
			cout << str1 << " + " << str2 << " = " << StoI(str1) + StoI(str2) << endl;
			break;
		}
		catch (char ch)//에러가 문자면 여기서 처리
		{
			cout << "문자 " << ch << "가 입력되었습니다." << endl;
			cout << "재입력 진행합니다." << endl << endl;
		}
		catch (int expn)//에러가 int형이면 여기서 처리
		{
			if (expn == 0)
				cout << "0으로 시작하는 숫자는 입력불가." << endl;
			else
				cout << "비정상적 입력이 이루어졌습니다." << endl;

			cout << "재입력 진행합니다." << endl << endl;
		}
	}
	cout << "프로그램을 종료합니다." << endl;
	return 0;
}
```
## 5. 전달되는 예외의 명시
> 함수를 정의하는 부분에서 예외데이터의 발생가능한 형태를 명시하는 게 좋다.
```C++
int ThrowFunc(int num) throw (int,char)
{
  ...
}
```
> 이렇게 명시를 해주면 예외처리를 
> 
```C++
try
{
  ThrowFunc(20);
}
catch(int expn){...}//<-- catch되지않는 자료형의 에러가 생기면 에러를 처리하지않고 unexpected함수를 호출하며 terminate된다.
catch(char expn){...}
```
> 예상해서 만들어 줄 수 있다.
